Workbook
Name ciselnik_anchor: Ciselniky!$A$2:$A$100
Name ciselnik_dodavatel: Ciselniky!$B$2:$B$100
Name ciselnik_stav: Ciselniky!$D$2:$D$10
Name portfolio_stage: Parametry!$B$27
Name portfolio_total: Parametry!$B$28

Sheet Přehled
A1: Přehled portfolia — souhrn nad daty ze listu Scoring
A3: Počet dealů | B3: =COUNTIF(Scoring!E6:E45,">0") -> 8 | D3: Risk band | E3: Počet | G3: Rating gate | H3: Počet
A4: Dealů s částkou | B4: =COUNT(Scoring!E6:E45) -> 8 | D4: Nízké riziko | E4: =COUNTIF(Scoring!AA6:AA45,D4) -> 4 | G4: OK | H4: =COUNTIF(Scoring!AW6:AW45,G4) -> 7
A5: Průměrné skóre | B5: =IFERROR(AVERAGEIF(Scoring!Z6:Z45,">0"),0) -> 74.875 | D5: Střední riziko | E5: =COUNTIF(Scoring!AA6:AA45,D5) -> 3 | G5: MANUAL | H5: =COUNTIF(Scoring!AW6:AW45,G5) -> 1
A6: Celková faktura (Kč) | B6: =SUM(Scoring!E6:E45) -> 5800000 | D6: Watchlist | E6: =COUNTIF(Scoring!AA6:AA45,D6) -> 0 | G6: STOP | H6: =COUNTIF(Scoring!AW6:AW45,G6) -> 0
A7: Doporučené financování (Kč) | B7: =SUMPRODUCT(Scoring!E6:E45,Scoring!AB6:AB45) -> 3825000 | D7: Stop | E7: =COUNTIF(Scoring!AA6:AA45,D7) -> 1
A8: Průměrný advance % | B8: =IFERROR(AVERAGEIF(Scoring!AB6:AB45,">0"),0) -> 0.77857143 | G8: Dealů s ratingem >= BBB | H8: =COUNTIFS(Scoring!AT6:AT45,"AAA")+COUNTIFS(Scoring!AT6:AT45,"AA")+COUNTIFS(Scoring!AT6:AT45,"A")+COUNTIFS(Scoring!AT6:AT45,"BBB") -> 7
A10: Koncentrace — doplňkový přehled
A11: Max. podíl jednoho anchoru v portfoliu | B11: =IFERROR(MAX(Scoring!AI6:AI45),0) -> 0.51724138 | C11: (podíl)
A12: Max. podíl jednoho řádku (supplier/deal) v portfoliu | B12: =IFERROR(MAX(Scoring!AJ6:AJ45),0) -> 0.43103448 | C12: (podíl)
A13: Podíl top 3 anchorů (součet expozic / portfolio) | B13: =IF(Parametry!$B$28=0,0,(IFERROR(LARGE(Scoring!$AM$6:$AM$45,1),0)+IFERROR(LARGE(Scoring!$AM$6:$AM$45,2),0)+IFERROR(LARGE(Scoring!$AM$6:$AM$45,3),0))/Parametry!$B$28) -> 0.96551724
A14: Kontrola koncentrace top 3 | B14: =IF(B13>0.5,"VAROVÁNÍ: top 3 anchori > 50 % portfolia","OK") -> VAROVÁNÍ: top 3 anchori > 50 % portfolia
A16: Top 5 anchorů podle expozice | D16: Anchor | E16: Expozice (Kč)
D17: =IF(E17="","",INDEX(Scoring!$A$6:$A$45,MATCH(E17,Scoring!$AM$6:$AM$45,0))) -> Maersk | E17: =IFERROR(LARGE(Scoring!$AM$6:$AM$45,1),"") -> 3000000
D18: =IF(E18="","",INDEX(Scoring!$A$6:$A$45,MATCH(E18,Scoring!$AM$6:$AM$45,0))) -> Tesco | E18: =IFERROR(LARGE(Scoring!$AM$6:$AM$45,2),"") -> 1700000
D19: =IF(E19="","",INDEX(Scoring!$A$6:$A$45,MATCH(E19,Scoring!$AM$6:$AM$45,0))) -> Anchor B | E19: =IFERROR(LARGE(Scoring!$AM$6:$AM$45,3),"") -> 900000
D20: =IF(E20="","",INDEX(Scoring!$A$6:$A$45,MATCH(E20,Scoring!$AM$6:$AM$45,0))) -> Anchor C | E20: =IFERROR(LARGE(Scoring!$AM$6:$AM$45,4),"") -> 200000
A21: Splatnosti a otevřené (ze Scoring AH–AL) | D21: =IF(E21="","",INDEX(Scoring!$A$6:$A$45,MATCH(E21,Scoring!$AM$6:$AM$45,0))) | E21: =IFERROR(LARGE(Scoring!$AM$6:$AM$45,5),"")
A22: Nejkratší dní do splatnosti (aktivní pohledávky) | B22: =IFERROR(_xludf.aggregate(15,6,Scoring!AP6:AP45,1),"")
A23: Nejdelší dní do splatnosti (aktivní pohledávky) | B23: =IFERROR(_xludf.aggregate(14,6,Scoring!AP6:AP45,1),"")
A24: Největší otevřená expozice jednoho anchoru (řádek) | B24: =IFERROR(MAX(Scoring!AN6:AN45),0) -> 2600000
A25: Největší otevřená expozice jednoho dodavatele (řádek) | B25: =IFERROR(MAX(Scoring!AO6:AO45),0) -> 2500000

Sheet Schvaleni
A1: Rychlý přehled — je faktura vhodná ke schválení? (data ze Scoring)
A2: Čtěte sloupec „Závěr“. Zelená = vhodné, žlutá = s limitem/opatrně, červená = zamítnout, tmavá = STOP. Podrobnosti vždy na listu Scoring.
A5: Deal ID | B5: Anchor | C5: Dodavatel | D5: Částka (Kč) | E5: Skóre | F5: Risk band | G5: Doporučení | H5: Koncentrace | I5: ZÁVĚR | J5: Jedním pohledem | K5: kód
A6: =Scoring!D6 -> D001 | B6: =Scoring!A6 -> Maersk | C6: =Scoring!B6 -> AVS | D6: =Scoring!E6 -> 2500000 | E6: =Scoring!Z6 -> 87 | F6: =Scoring!AA6 -> Nízké riziko | G6: =Scoring!AD6 -> Financovat | H6: =Scoring!AL6 -> EARLY STAGE EXCEPTION | I6: =Scoring!AR6 -> Schválit s výhradou (koncentrace / early stage) | J6: =Scoring!AS6 -> 87 b | Nízké riziko | Financovat | gate OK | rating AA | K6: =Scoring!AQ6 -> 2
A7: =Scoring!D7 -> D002 | B7: =Scoring!A7 -> Anchor B | C7: =Scoring!B7 -> Dodavatel B | D7: =Scoring!E7 -> 900000 | E7: =Scoring!Z7 -> 34 | F7: =Scoring!AA7 -> Stop | G7: =Scoring!AD7 -> Stop | H7: =Scoring!AL7 -> EARLY STAGE EXCEPTION | I7: =Scoring!AR7 -> STOP | J7: =Scoring!AS7 -> 34 b | Stop | Stop | gate MANUAL | rating BB | K7: =Scoring!AQ7 -> 5
A8: =Scoring!D8 -> D003 | B8: =Scoring!A8 -> Anchor C | C8: =Scoring!B8 -> Dodavatel C | D8: =Scoring!E8 -> 200000 | E8: =Scoring!Z8 -> 71 | F8: =Scoring!AA8 -> Střední riziko | G8: =Scoring!AD8 -> Financovat s limitem | H8: =Scoring!AL8 -> EARLY STAGE EXCEPTION | I8: =Scoring!AR8 -> Schválit s výhradou (koncentrace / early stage) | J8: =Scoring!AS8 -> 71 b | Střední riziko | Financovat s limitem | gate OK | rating BBB | K8: =Scoring!AQ8 -> 2
A9: =Scoring!D9 -> D004 | B9: =Scoring!A9 -> Maersk | C9: =Scoring!B9 -> Dodavatel C | D9: =Scoring!E9 -> 100000 | E9: =Scoring!Z9 -> 89 | F9: =Scoring!AA9 -> Nízké riziko | G9: =Scoring!AD9 -> Financovat | H9: =Scoring!AL9 -> EARLY STAGE EXCEPTION | I9: =Scoring!AR9 -> Schválit s výhradou (koncentrace / early stage) | J9: =Scoring!AS9 -> 89 b | Nízké riziko | Financovat | gate OK | rating AA | K9: =Scoring!AQ9 -> 2
A10: =Scoring!D10 -> D005 | B10: =Scoring!A10 -> Maersk | C10: =Scoring!B10 -> AVS | D10: =Scoring!E10 -> 200000 | E10: =Scoring!Z10 -> 89 | F10: =Scoring!AA10 -> Nízké riziko | G10: =Scoring!AD10 -> Financovat | H10: =Scoring!AL10 -> EARLY STAGE EXCEPTION | I10: =Scoring!AR10 -> Schválit s výhradou (koncentrace / early stage) | J10: =Scoring!AS10 -> 89 b | Nízké riziko | Financovat | gate OK | rating AA | K10: =Scoring!AQ10 -> 2
A11: =Scoring!D11 -> D006 | B11: =Scoring!A11 -> Tesco | C11: =Scoring!B11 -> Bruggy | D11: =Scoring!E11 -> 850000 | E11: =Scoring!Z11 -> 70 | F11: =Scoring!AA11 -> Střední riziko | G11: =Scoring!AD11 -> Financovat s limitem | H11: =Scoring!AL11 -> EARLY STAGE EXCEPTION | I11: =Scoring!AR11 -> Schválit s výhradou (koncentrace / early stage) | J11: =Scoring!AS11 -> 70 b | Střední riziko | Financovat s limitem | gate OK | rating A | K11: =Scoring!AQ11 -> 2
A12: =Scoring!D12 -> D007 | B12: =Scoring!A12 -> Maersk | C12: =Scoring!B12 -> AVS | D12: =Scoring!E12 -> 200000 | E12: =Scoring!Z12 -> 89 | F12: =Scoring!AA12 -> Nízké riziko | G12: =Scoring!AD12 -> Financovat | H12: =Scoring!AL12 -> EARLY STAGE EXCEPTION | I12: =Scoring!AR12 -> Schválit s výhradou (koncentrace / early stage) | J12: =Scoring!AS12 -> 89 b | Nízké riziko | Financovat | gate OK | rating AA | K12: =Scoring!AQ12 -> 2
A13: =Scoring!D13 -> D008 | B13: =Scoring!A13 -> Tesco | C13: =Scoring!B13 -> Bruggy | D13: =Scoring!E13 -> 850000 | E13: =Scoring!Z13 -> 70 | F13: =Scoring!AA13 -> Střední riziko | G13: =Scoring!AD13 -> Financovat s limitem | H13: =Scoring!AL13 -> EARLY STAGE EXCEPTION | I13: =Scoring!AR13 -> Schválit s výhradou (koncentrace / early stage) | J13: =Scoring!AS13 -> 70 b | Střední riziko | Financovat s limitem | gate OK | rating A | K13: =Scoring!AQ13 -> 2
A14: =Scoring!D14 -> 0 | B14: =Scoring!A14 -> 0 | C14: =Scoring!B14 -> 0 | D14: =Scoring!E14 -> 0 | E14: =Scoring!Z14 | F14: =Scoring!AA14 | G14: =Scoring!AD14 | H14: =Scoring!AL14 | I14: =Scoring!AR14 | J14: =Scoring!AS14 | K14: =Scoring!AQ14
A15: =Scoring!D15 -> 0 | B15: =Scoring!A15 -> 0 | C15: =Scoring!B15 -> 0 | D15: =Scoring!E15 -> 0 | E15: =Scoring!Z15 | F15: =Scoring!AA15 | G15: =Scoring!AD15 | H15: =Scoring!AL15 | I15: =Scoring!AR15 | J15: =Scoring!AS15 | K15: =Scoring!AQ15
A16: =Scoring!D16 -> 0 | B16: =Scoring!A16 -> 0 | C16: =Scoring!B16 -> 0 | D16: =Scoring!E16 -> 0 | E16: =Scoring!Z16 | F16: =Scoring!AA16 | G16: =Scoring!AD16 | H16: =Scoring!AL16 | I16: =Scoring!AR16 | J16: =Scoring!AS16 | K16: =Scoring!AQ16
A17: =Scoring!D17 -> 0 | B17: =Scoring!A17 -> 0 | C17: =Scoring!B17 -> 0 | D17: =Scoring!E17 -> 0 | E17: =Scoring!Z17 | F17: =Scoring!AA17 | G17: =Scoring!AD17 | H17: =Scoring!AL17 | I17: =Scoring!AR17 | J17: =Scoring!AS17 | K17: =Scoring!AQ17
... A45: =Scoring!D45 -> 0 | B45: =Scoring!A45 -> 0 | C45: =Scoring!B45 -> 0 | D45: =Scoring!E45 -> 0 | E45: =Scoring!Z45 | F45: =Scoring!AA45 | G45: =Scoring!AD45 | H45: =Scoring!AL45 | I45: =Scoring!AR45 | J45: =Scoring!AS45 | K45: =Scoring!AQ45

Sheet Scoring
A1: Scoring — nejdřív vyplňte A–H, rating anchora udržujte v Ciselniky, výsledek schválení je v AR–AS (→)
A2: 1) KROK POVINNÝ — výběr z číselníků (A–C) a údaje dealu (D–H) | I2: 2) Historie plateb — dopočítáno z listu Historie | N2: Splatnost | P2: 3) Skóre a rozhodnutí | AE2: 4) Koncentrace | AM2: Pomocné a expozice | AT2: 5) Anchor-centric overlay
A3: Anchor a dodavatel vybírejte jen z listu Ciselniky. Stav pohledávky také z číselníku. | AT3: Rating anchora se bere z listu Ciselniky (anchor master). Pokud rating chybí, model přepne deal na NR / manuální review.
A5: Anchor | B5: Dodavatel | C5: Stav pohledávky | D5: Deal ID | E5: Aktuální faktura (Kč) | F5: Datum splatnosti | G5: Nesoulad dat? | H5: Spor? | I5: Počet uhrazených faktur | J5: Prům. zpoždění (dny) | K5: Podíl pozdních faktur | L5: Vztah (měsíce) | M5: Prům. hist. faktura (Kč) | N5: Dní do splatnosti | O5: Dní do splatnosti (aktivní) | P5: Nový anchor? | Q5: Poměr objemu | R5: Body: historie | S5: Body: delay | T5: Body: volatilita | U5: Body: vztah | V5: Body: objem | W5: Pen.: nový | X5: Pen.: mismatch | Y5: Pen.: spor | Z5: Skóre | AA5: Risk band | AB5: Advance % | AC5: Fee % | AD5: Doporučení | AE5: supplier_exposure | AF5: anchor_exposure | AG5: total_portfolio_exposure | AH5: supplier_to_anchor_pct | AI5: anchor_to_portfolio_pct | AJ5: supplier_to_portfolio_pct | AK5: concentration_score | AL5: concentration_flag | AM5: helper_anchor_exp_1x | AN5: Otevřená expozice anchoru (Kč) | AO5: Otevřená expozice dodavatele (Kč) | AP5: Dní aktivní (AO) | AQ5: Výsledek (kód) | AR5: ZÁVĚR SCHVÁLENÍ | AS5: Shrnutí pro řízení | AT5: Anchor rating | AU5: Zdroj ratingu | AV5: Anchor rating score | AW5: Rating gate | AX5: Behavior score raw | AY5: Body: rating | AZ5: Body: behavior | BA5: Body: koncentrace | BB5: Pen.: rating / gate
A6: Maersk | B6: AVS | C6: Otevřená | D6: D001 | E6: 2500000 | F6: 46188 | G6: NE | H6: NE | I6: =IF(A6="","",IF(AND(Parametry!$B$39="ANO",B6<>""),COUNTIFS(Historie!$A$2:$A$2000,A6,Historie!$B$2:$B$2000,B6,Historie!$E$2:$E$2000,"<>"),COUNTIFS(Historie!$A$2:$A$2000,A6,Historie!$E$2:$E$2000,"<>"))) -> 7 | J6: =IF(I6=0,"",IFERROR(IF(AND(Parametry!$B$39="ANO",B6<>""),AVERAGEIFS(Historie!$F$2:$F$2000,Historie!$A$2:$A$2000,A6,Historie!$B$2:$B$2000,B6,Historie!$E$2:$E$2000,"<>"),AVERAGEIFS(Historie!$F$2:$F$2000,Historie!$A$2:$A$2000,A6,Historie!$E$2:$E$2000,"<>")),"")) -> -0.14285714 | K6: =IF(I6=0,"",IFERROR(IF(AND(Parametry!$B$39="ANO",B6<>""),COUNTIFS(Historie!$A$2:$A$2000,A6,Historie!$B$2:$B$2000,B6,Historie!$E$2:$E$2000,"<>",Historie!$F$2:$F$2000,">0")/I6,COUNTIFS(Historie!$A$2:$A$2000,A6,Historie!$E$2:$E$2000,"<>",Historie!$F$2:$F$2000,">0")/I6),0)) -> 0.14285714 | L6: =IF(OR(A6="",I6=0),"",IFERROR(DATEDIF(IF(AND(Parametry!$B$39="ANO",B6<>""),_xludf.minifs(Historie!$E$2:$E$2000,Historie!$A$2:$A$2000,A6,Historie!$B$2:$B$2000,B6,Historie!$E$2:$E$2000,"<>"),_xludf.minifs(Historie!$E$2:$E$2000,Historie!$A$2:$A$2000,A6,Historie!$E$2:$E$2000,"<>")),IF(AND(Parametry!$B$39="ANO",B6<>""),_xludf.maxifs(Historie!$E$2:$E$2000,Historie!$A$2:$A$2000,A6,Historie!$B$2:$B$2000,B6,Historie!$E$2:$E$2000,"<>"),_xludf.maxifs(Historie!$E$2:$E$2000,Historie!$A$2:$A$2000,A6,Historie!$E$2:$E$2000,"<>")),"M"),0)) -> 0 | M6: =IF(A6="","",IFERROR(IF(AND(Parametry!$B$39="ANO",B6<>""),AVERAGEIFS(Historie!$C$2:$C$2000,Historie!$A$2:$A$2000,A6,Historie!$B$2:$B$2000,B6,Historie!$E$2:$E$2000,"<>"),AVERAGEIFS(Historie!$C$2:$C$2000,Historie!$A$2:$A$2000,A6,Historie!$E$2:$E$2000,"<>")),"")) -> 1847142.9 | N6: =IF(F6="","",F6-TODAY()) -> 68 | O6: =IF(OR(A6="",E6=""),"",IF(C6="Uhrazená","",N6)) -> 68 | P6: =IF(OR(A6="",E6=""),"",IF(I6=0,"ANO","NE")) -> NE | Q6: =IF(OR(A6="",E6="",M6=0),"",IFERROR(E6/M6,"")) -> 1.3534416 | R6: =IF(OR(A6="",E6=""),"",IF(I6>=Parametry!$B$4,Parametry!$B$9,0)) -> 40 | S6: =IF(OR(A6="",E6=""),"",IF(I6>0,IF(J6<=Parametry!$B$5,Parametry!$B$10,0),0)) -> 20 | T6: =IF(OR(A6="",E6=""),"",IF(I6>0,IF(K6<=Parametry!$B$6,Parametry!$B$11,0),0)) -> 15 | U6: =IF(OR(A6="",E6=""),"",IF(L6>=Parametry!$B$7,Parametry!$B$12,0)) -> 0 | V6: =IF(OR(A6="",E6=""),"",IF(M6>0,IF(Q6<=Parametry!$B$8,Parametry!$B$13,0),0)) -> 10 | W6: =IF(OR(A6="",E6=""),"",IF(P6="ANO",Parametry!$B$14,0)) -> 0 | X6: =IF(OR(A6="",E6=""),"",IF(G6="ANO",Parametry!$B$15,0)) -> 0 | Y6: =IF(OR(A6="",E6=""),"",IF(H6="ANO",Parametry!$B$16,0)) -> 0 | Z6: =IF(OR(A6="",E6=""),"",MAX(0,MIN(100,ROUND(AY6+AZ6+BA6+BB6,0)))) -> 87 | AA6: =IF(Z6="","",IF(AW6="STOP","Stop",IF(AW6="MANUAL",IF(Z6>=Parametry!$B$19,"Watchlist","Stop"),IF(Z6>=Parametry!$B$17,"Nízké riziko",IF(Z6>=Parametry!$B$18,"Střední riziko",IF(Z6>=Parametry!$B$19,"Watchlist","Stop")))))) -> Nízké riziko | AB6: =IF(AA6="","",MIN(IF(AA6="Nízké riziko",Parametry!$B$20,IF(AA6="Střední riziko",Parametry!$B$21,IF(AA6="Watchlist",Parametry!$B$22,Parametry!$B$23))),IFERROR(INDEX(Ciselniky!$H$3:$H$10,MATCH(AT6,Ciselniky!$F$3:$F$10,0)),0))) -> 0.8 | AC6: =IF(AA6="","",IF(AA6="Stop",0,IF(AA6="Nízké riziko",Parametry!$B$24,IF(AA6="Střední riziko",Parametry!$B$25,IF(AA6="Watchlist",Parametry!$B$26,0)))+IFERROR(INDEX(Ciselniky!$I$3:$I$10,MATCH(AT6,Ciselniky!$F$3:$F$10,0)),0))) -> 0.025 | AD6: =IF(AA6="","",IF(OR(AA6="Stop",AW6="STOP"),"Stop",IF(AW6="MANUAL","Pouze manuálně",IF(AA6="Nízké riziko","Financovat",IF(AA6="Střední riziko","Financovat s limitem",IF(AA6="Watchlist","Pouze manuálně","Stop")))))) -> Financovat | AE6: =E6 -> 2500000 | AF6: =SUMIF($A$6:$A$45,A6,$E$6:$E$45) -> 3000000 | AG6: =Parametry!$B$28 -> 5800000 | AH6: =IFERROR(AE6/AF6,"") -> 0.83333333 | AI6: =IFERROR(AF6/Parametry!$B$28,"") -> 0.51724138 | AJ6: =IFERROR(AE6/Parametry!$B$28,"") -> 0.43103448 | AK6: =IF(OR(A6="",E6=""),"",MAX(0,100-IF(Parametry!$B$27="early",0.5,IF(Parametry!$B$27="growth",0.75,1))*(IF(AI6<=Parametry!$B$34,0,IF(AI6<=Parametry!$B$34+0.05,8,20))+IF(AH6<=Parametry!$B$35,0,12)+IF(AJ6<=Parametry!$B$36,0,12)))) -> 78 | AL6: =IF(OR(A6="",E6=""),"",IF(Parametry!$B$27="early",IF(OR(AI6>Parametry!$B$34*1.2,AH6>Parametry!$B$35*1.3),"EARLY STAGE EXCEPTION","OK"),IF(Parametry!$B$27="growth",IF(OR(AI6>Parametry!$B$34*1.35,AH6>Parametry!$B$35*1.4),"RED FLAG","OK"),IF(OR(AI6>Parametry!$B$34*1.2,AH6>Parametry!$B$35*1.3),"RED FLAG","OK")))) -> EARLY STAGE EXCEPTION | AM6: =IF(OR(A6="",E6=""),"",IF(COUNTIF($A$6:A6,A6)=1,AF6,"")) -> 3000000 | AN6: =IF(A6="","",SUMPRODUCT(($A$6:$A$45=A6)*($E$6:$E$45)*((($C$6:$C$45="")+($C$6:$C$45="Otevřená"))>0))) -> 2600000 | AO6: =IF(OR(B6="",A6=""),"",SUMPRODUCT(($B$6:$B$45=B6)*($E$6:$E$45)*((($C$6:$C$45="")+($C$6:$C$45="Otevřená"))>0))) -> 2500000 | AP6: =IF(OR(A6="",E6=""),"",IF(C6="Uhrazená","",N6)) -> 68 | AQ6: =IF(OR(A6="",E6=""),"",IF(OR(AW6="STOP",AA6="Stop"),5,IF(OR(G6="ANO",H6="ANO"),4,IF(AL6="RED FLAG",4,IF(OR(AW6="MANUAL",AA6="Watchlist"),3,IF(OR(AL6="EARLY STAGE EXCEPTION",AA6="Střední riziko"),2,IF(AA6="Nízké riziko",1,5))))))) -> 2 | AR6: =IF(OR(A6="",E6=""),"",IF(OR(AQ6="",NOT(ISNUMBER(AQ6))),"",IF(AQ6=1,"Vhodné ke schválení",IF(AQ6=2,"Schválit s výhradou (koncentrace / early stage)",IF(AQ6=3,"Pouze manuálně - anchor rating / watchlist",IF(AQ6=4,"Zamítnout - spor, nesoulad nebo koncentrace",IF(AQ6=5,"STOP",""))))))) -> Schválit s výhradou (koncentrace / early stage) | AS6: =IF(A6="","",TEXT(Z6,"0") & " b | " & AA6 & " | " & AD6 & " | gate " & AW6 & " | rating " & AT6) -> 87 b | Nízké riziko | Financovat | gate OK | rating AA | AT6: =IF(A6="","",IF(COUNTIF(Ciselniky!$L$3:$L$200,A6)=0,"NR",IF(INDEX(Ciselniky!$M$3:$M$200,MATCH(A6,Ciselniky!$L$3:$L$200,0))="","NR",INDEX(Ciselniky!$M$3:$M$200,MATCH(A6,Ciselniky!$L$3:$L$200,0))))) -> AA | AU6: =IF(A6="","",IF(AT6="NR","doplňit rating v Ciselniky",IFERROR(IF(INDEX(Ciselniky!$N$3:$N$200,MATCH(A6,Ciselniky!$L$3:$L$200,0))="","anchor master",INDEX(Ciselniky!$N$3:$N$200,MATCH(A6,Ciselniky!$L$3:$L$200,0))),"anchor master"))) -> doplňte interní / externí rating | AV6: =IF(AT6="","",IFERROR(INDEX(Ciselniky!$G$3:$G$10,MATCH(AT6,Ciselniky!$F$3:$F$10,0)),0)) -> 90 | AW6: =IF(AT6="","",IFERROR(INDEX(Ciselniky!$J$3:$J$10,MATCH(AT6,Ciselniky!$F$3:$F$10,0)),"MANUAL")) -> OK | AX6: =IF(OR(A6="",E6=""),"",MAX(0,MIN(100,SUM(R6:Y6)))) -> 85 | AY6: =IF(OR(A6="",E6=""),"",AV6*Parametry!$B$41) -> 54 | AZ6: =IF(OR(A6="",E6=""),"",AX6*Parametry!$B$42) -> 21.25 | BA6: =IF(OR(A6="",E6=""),"",AK6*Parametry!$B$43) -> 11.7 | BB6: =IF(OR(A6="",E6=""),"",IF(AW6="STOP",-100,IF(AT6="BB",Parametry!$B$47,IF(AT6="NR",Parametry!$B$48,0)))) -> 0
A7: Anchor B | B7: Dodavatel B | C7: Otevřená | D7: D002 | E7: 900000 | F7: 46193 | G7: NE | H7: NE | I7: =IF(A7="","",IF(AND(Parametry!$B$39="ANO",B7<>""),COUNTIFS(Historie!$A$2:$A$2000,A7,Historie!$B$2:$B$2000,B7,Historie!$E$2:$E$2000,"<>"),COUNTIFS(Historie!$A$2:$A$2000,A7,Historie!$E$2:$E$2000,"<>"))) -> 4 | J7: =IF(I7=0,"",IFERROR(IF(AND(Parametry!$B$39="ANO",B7<>""),AVERAGEIFS(Historie!$F$2:$F$2000,Historie!$A$2:$A$2000,A7,Historie!$B$2:$B$2000,B7,Historie!$E$2:$E$2000,"<>"),AVERAGEIFS(Historie!$F$2:$F$2000,Historie!$A$2:$A$2000,A7,Historie!$E$2:$E$2000,"<>")),"")) -> 2.5 | K7: =IF(I7=0,"",IFERROR(IF(AND(Parametry!$B$39="ANO",B7<>""),COUNTIFS(Historie!$A$2:$A$2000,A7,Historie!$B$2:$B$2000,B7,Historie!$E$2:$E$2000,"<>",Historie!$F$2:$F$2000,">0")/I7,COUNTIFS(Historie!$A$2:$A$2000,A7,Historie!$E$2:$E$2000,"<>",Historie!$F$2:$F$2000,">0")/I7),0)) -> 0.5 | L7: =IF(OR(A7="",I7=0),"",IFERROR(DATEDIF(IF(AND(Parametry!$B$39="ANO",B7<>""),_xludf.minifs(Historie!$E$2:$E$2000,Historie!$A$2:$A$2000,A7,Historie!$B$2:$B$2000,B7,Historie!$E$2:$E$2000,"<>"),_xludf.minifs(Historie!$E$2:$E$2000,Historie!$A$2:$A$2000,A7,Historie!$E$2:$E$2000,"<>")),IF(AND(Parametry!$B$39="ANO",B7<>""),_xludf.maxifs(Historie!$E$2:$E$2000,Historie!$A$2:$A$2000,A7,Historie!$B$2:$B$2000,B7,Historie!$E$2:$E$2000,"<>"),_xludf.maxifs(Historie!$E$2:$E$2000,Historie!$A$2:$A$2000,A7,Historie!$E$2:$E$2000,"<>")),"M"),0)) -> 0 | M7: =IF(A7="","",IFERROR(IF(AND(Parametry!$B$39="ANO",B7<>""),AVERAGEIFS(Historie!$C$2:$C$2000,Historie!$A$2:$A$2000,A7,Historie!$B$2:$B$2000,B7,Historie!$E$2:$E$2000,"<>"),AVERAGEIFS(Historie!$C$2:$C$2000,Historie!$A$2:$A$2000,A7,Historie!$E$2:$E$2000,"<>")),"")) -> 922500 | N7: =IF(F7="","",F7-TODAY()) -> 73 | O7: =IF(OR(A7="",E7=""),"",IF(C7="Uhrazená","",N7)) -> 73 | P7: =IF(OR(A7="",E7=""),"",IF(I7=0,"ANO","NE")) -> NE | Q7: =IF(OR(A7="",E7="",M7=0),"",IFERROR(E7/M7,"")) -> 0.97560976 | R7: =IF(OR(A7="",E7=""),"",IF(I7>=Parametry!$B$4,Parametry!$B$9,0)) -> 0 | S7: =IF(OR(A7="",E7=""),"",IF(I7>0,IF(J7<=Parametry!$B$5,Parametry!$B$10,0),0)) -> 20 | T7: =IF(OR(A7="",E7=""),"",IF(I7>0,IF(K7<=Parametry!$B$6,Parametry!$B$11,0),0)) -> 0 | U7: =IF(OR(A7="",E7=""),"",IF(L7>=Parametry!$B$7,Parametry!$B$12,0)) -> 0 | V7: =IF(OR(A7="",E7=""),"",IF(M7>0,IF(Q7<=Parametry!$B$8,Parametry!$B$13,0),0)) -> 10 | W7: =IF(OR(A7="",E7=""),"",IF(P7="ANO",Parametry!$B$14,0)) -> 0 | X7: =IF(OR(A7="",E7=""),"",IF(G7="ANO",Parametry!$B$15,0)) -> 0 | Y7: =IF(OR(A7="",E7=""),"",IF(H7="ANO",Parametry!$B$16,0)) -> 0 | Z7: =IF(OR(A7="",E7=""),"",MAX(0,MIN(100,ROUND(AY7+AZ7+BA7+BB7,0)))) -> 34 | AA7: =IF(Z7="","",IF(AW7="STOP","Stop",IF(AW7="MANUAL",IF(Z7>=Parametry!$B$19,"Watchlist","Stop"),IF(Z7>=Parametry!$B$17,"Nízké riziko",IF(Z7>=Parametry!$B$18,"Střední riziko",IF(Z7>=Parametry!$B$19,"Watchlist","Stop")))))) -> Stop | AB7: =IF(AA7="","",MIN(IF(AA7="Nízké riziko",Parametry!$B$20,IF(AA7="Střední riziko",Parametry!$B$21,IF(AA7="Watchlist",Parametry!$B$22,Parametry!$B$23))),IFERROR(INDEX(Ciselniky!$H$3:$H$10,MATCH(AT7,Ciselniky!$F$3:$F$10,0)),0))) -> 0 | AC7: =IF(AA7="","",IF(AA7="Stop",0,IF(AA7="Nízké riziko",Parametry!$B$24,IF(AA7="Střední riziko",Parametry!$B$25,IF(AA7="Watchlist",Parametry!$B$26,0)))+IFERROR(INDEX(Ciselniky!$I$3:$I$10,MATCH(AT7,Ciselniky!$F$3:$F$10,0)),0))) -> 0 | AD7: =IF(AA7="","",IF(OR(AA7="Stop",AW7="STOP"),"Stop",IF(AW7="MANUAL","Pouze manuálně",IF(AA7="Nízké riziko","Financovat",IF(AA7="Střední riziko","Financovat s limitem",IF(AA7="Watchlist","Pouze manuálně","Stop")))))) -> Stop | AE7: =E7 -> 900000 | AF7: =SUMIF($A$6:$A$45,A7,$E$6:$E$45) -> 900000 | AG7: =Parametry!$B$28 -> 5800000 | AH7: =IFERROR(AE7/AF7,"") -> 1 | AI7: =IFERROR(AF7/Parametry!$B$28,"") -> 0.15517241 | AJ7: =IFERROR(AE7/Parametry!$B$28,"") -> 0.15517241 | AK7: =IF(OR(A7="",E7=""),"",MAX(0,100-IF(Parametry!$B$27="early",0.5,IF(Parametry!$B$27="growth",0.75,1))*(IF(AI7<=Parametry!$B$34,0,IF(AI7<=Parametry!$B$34+0.05,8,20))+IF(AH7<=Parametry!$B$35,0,12)+IF(AJ7<=Parametry!$B$36,0,12)))) -> 94 | AL7: =IF(OR(A7="",E7=""),"",IF(Parametry!$B$27="early",IF(OR(AI7>Parametry!$B$34*1.2,AH7>Parametry!$B$35*1.3),"EARLY STAGE EXCEPTION","OK"),IF(Parametry!$B$27="growth",IF(OR(AI7>Parametry!$B$34*1.35,AH7>Parametry!$B$35*1.4),"RED FLAG","OK"),IF(OR(AI7>Parametry!$B$34*1.2,AH7>Parametry!$B$35*1.3),"RED FLAG","OK")))) -> EARLY STAGE EXCEPTION | AM7: =IF(OR(A7="",E7=""),"",IF(COUNTIF($A$6:A7,A7)=1,AF7,"")) -> 900000 | AN7: =IF(A7="","",SUMPRODUCT(($A$6:$A$45=A7)*($E$6:$E$45)*((($C$6:$C$45="")+($C$6:$C$45="Otevřená"))>0))) -> 900000 | AO7: =IF(OR(B7="",A7=""),"",SUMPRODUCT(($B$6:$B$45=B7)*($E$6:$E$45)*((($C$6:$C$45="")+($C$6:$C$45="Otevřená"))>0))) -> 900000 | AP7: =IF(OR(A7="",E7=""),"",IF(C7="Uhrazená","",N7)) -> 73 | AQ7: =IF(OR(A7="",E7=""),"",IF(OR(AW7="STOP",AA7="Stop"),5,IF(OR(G7="ANO",H7="ANO"),4,IF(AL7="RED FLAG",4,IF(OR(AW7="MANUAL",AA7="Watchlist"),3,IF(OR(AL7="EARLY STAGE EXCEPTION",AA7="Střední riziko"),2,IF(AA7="Nízké riziko",1,5))))))) -> 5 | AR7: =IF(OR(A7="",E7=""),"",IF(OR(AQ7="",NOT(ISNUMBER(AQ7))),"",IF(AQ7=1,"Vhodné ke schválení",IF(AQ7=2,"Schválit s výhradou (koncentrace / early stage)",IF(AQ7=3,"Pouze manuálně - anchor rating / watchlist",IF(AQ7=4,"Zamítnout - spor, nesoulad nebo koncentrace",IF(AQ7=5,"STOP",""))))))) -> STOP | AS7: =IF(A7="","",TEXT(Z7,"0") & " b | " & AA7 & " | " & AD7 & " | gate " & AW7 & " | rating " & AT7) -> 34 b | Stop | Stop | gate MANUAL | rating BB | AT7: =IF(A7="","",IF(COUNTIF(Ciselniky!$L$3:$L$200,A7)=0,"NR",IF(INDEX(Ciselniky!$M$3:$M$200,MATCH(A7,Ciselniky!$L$3:$L$200,0))="","NR",INDEX(Ciselniky!$M$3:$M$200,MATCH(A7,Ciselniky!$L$3:$L$200,0))))) -> BB | AU7: =IF(A7="","",IF(AT7="NR","doplňit rating v Ciselniky",IFERROR(IF(INDEX(Ciselniky!$N$3:$N$200,MATCH(A7,Ciselniky!$L$3:$L$200,0))="","anchor master",INDEX(Ciselniky!$N$3:$N$200,MATCH(A7,Ciselniky!$L$3:$L$200,0))),"anchor master"))) -> demo / upravit | AV7: =IF(AT7="","",IFERROR(INDEX(Ciselniky!$G$3:$G$10,MATCH(AT7,Ciselniky!$F$3:$F$10,0)),0)) -> 45 | AW7: =IF(AT7="","",IFERROR(INDEX(Ciselniky!$J$3:$J$10,MATCH(AT7,Ciselniky!$F$3:$F$10,0)),"MANUAL")) -> MANUAL | AX7: =IF(OR(A7="",E7=""),"",MAX(0,MIN(100,SUM(R7:Y7)))) -> 30 | AY7: =IF(OR(A7="",E7=""),"",AV7*Parametry!$B$41) -> 27 | AZ7: =IF(OR(A7="",E7=""),"",AX7*Parametry!$B$42) -> 7.5 | BA7: =IF(OR(A7="",E7=""),"",AK7*Parametry!$B$43) -> 14.1 | BB7: =IF(OR(A7="",E7=""),"",IF(AW7="STOP",-100,IF(AT7="BB",Parametry!$B$47,IF(AT7="NR",Parametry!$B$48,0)))) -> -15
A8: Anchor C | B8: Dodavatel C | C8: Uhrazená | D8: D003 | E8: 200000 | F8: 46183 | G8: NE | H8: NE | I8: =IF(A8="","",IF(AND(Parametry!$B$39="ANO",B8<>""),COUNTIFS(Historie!$A$2:$A$2000,A8,Historie!$B$2:$B$2000,B8,Historie!$E$2:$E$2000,"<>"),COUNTIFS(Historie!$A$2:$A$2000,A8,Historie!$E$2:$E$2000,"<>"))) -> 12 | J8: =IF(I8=0,"",IFERROR(IF(AND(Parametry!$B$39="ANO",B8<>""),AVERAGEIFS(Historie!$F$2:$F$2000,Historie!$A$2:$A$2000,A8,Historie!$B$2:$B$2000,B8,Historie!$E$2:$E$2000,"<>"),AVERAGEIFS(Historie!$F$2:$F$2000,Historie!$A$2:$A$2000,A8,Historie!$E$2:$E$2000,"<>")),"")) -> 2.9166667 | K8: =IF(I8=0,"",IFERROR(IF(AND(Parametry!$B$39="ANO",B8<>""),COUNTIFS(Historie!$A$2:$A$2000,A8,Historie!$B$2:$B$2000,B8,Historie!$E$2:$E$2000,"<>",Historie!$F$2:$F$2000,">0")/I8,COUNTIFS(Historie!$A$2:$A$2000,A8,Historie!$E$2:$E$2000,"<>",Historie!$F$2:$F$2000,">0")/I8),0)) -> 0.58333333 | L8: =IF(OR(A8="",I8=0),"",IFERROR(DATEDIF(IF(AND(Parametry!$B$39="ANO",B8<>""),_xludf.minifs(Historie!$E$2:$E$2000,Historie!$A$2:$A$2000,A8,Historie!$B$2:$B$2000,B8,Historie!$E$2:$E$2000,"<>"),_xludf.minifs(Historie!$E$2:$E$2000,Historie!$A$2:$A$2000,A8,Historie!$E$2:$E$2000,"<>")),IF(AND(Parametry!$B$39="ANO",B8<>""),_xludf.maxifs(Historie!$E$2:$E$2000,Historie!$A$2:$A$2000,A8,Historie!$B$2:$B$2000,B8,Historie!$E$2:$E$2000,"<>"),_xludf.maxifs(Historie!$E$2:$E$2000,Historie!$A$2:$A$2000,A8,Historie!$E$2:$E$2000,"<>")),"M"),0)) -> 0 | M8: =IF(A8="","",IFERROR(IF(AND(Parametry!$B$39="ANO",B8<>""),AVERAGEIFS(Historie!$C$2:$C$2000,Historie!$A$2:$A$2000,A8,Historie!$B$2:$B$2000,B8,Historie!$E$2:$E$2000,"<>"),AVERAGEIFS(Historie!$C$2:$C$2000,Historie!$A$2:$A$2000,A8,Historie!$E$2:$E$2000,"<>")),"")) -> 1005000 | N8: =IF(F8="","",F8-TODAY()) -> 63 | O8: =IF(OR(A8="",E8=""),"",IF(C8="Uhrazená","",N8)) | P8: =IF(OR(A8="",E8=""),"",IF(I8=0,"ANO","NE")) -> NE | Q8: =IF(OR(A8="",E8="",M8=0),"",IFERROR(E8/M8,"")) -> 0.19900498 | R8: =IF(OR(A8="",E8=""),"",IF(I8>=Parametry!$B$4,Parametry!$B$9,0)) -> 40 | S8: =IF(OR(A8="",E8=""),"",IF(I8>0,IF(J8<=Parametry!$B$5,Parametry!$B$10,0),0)) -> 20 | T8: =IF(OR(A8="",E8=""),"",IF(I8>0,IF(K8<=Parametry!$B$6,Parametry!$B$11,0),0)) -> 0 | U8: =IF(OR(A8="",E8=""),"",IF(L8>=Parametry!$B$7,Parametry!$B$12,0)) -> 0 | V8: =IF(OR(A8="",E8=""),"",IF(M8>0,IF(Q8<=Parametry!$B$8,Parametry!$B$13,0),0)) -> 10 | W8: =IF(OR(A8="",E8=""),"",IF(P8="ANO",Parametry!$B$14,0)) -> 0 | X8: =IF(OR(A8="",E8=""),"",IF(G8="ANO",Parametry!$B$15,0)) -> 0 | Y8: =IF(OR(A8="",E8=""),"",IF(H8="ANO",Parametry!$B$16,0)) -> 0 | Z8: =IF(OR(A8="",E8=""),"",MAX(0,MIN(100,ROUND(AY8+AZ8+BA8+BB8,0)))) -> 71 | AA8: =IF(Z8="","",IF(AW8="STOP","Stop",IF(AW8="MANUAL",IF(Z8>=Parametry!$B$19,"Watchlist","Stop"),IF(Z8>=Parametry!$B$17,"Nízké riziko",IF(Z8>=Parametry!$B$18,"Střední riziko",IF(Z8>=Parametry!$B$19,"Watchlist","Stop")))))) -> Střední riziko | AB8: =IF(AA8="","",MIN(IF(AA8="Nízké riziko",Parametry!$B$20,IF(AA8="Střední riziko",Parametry!$B$21,IF(AA8="Watchlist",Parametry!$B$22,Parametry!$B$23))),IFERROR(INDEX(Ciselniky!$H$3:$H$10,MATCH(AT8,Ciselniky!$F$3:$F$10,0)),0))) -> 0.75 | AC8: =IF(AA8="","",IF(AA8="Stop",0,IF(AA8="Nízké riziko",Parametry!$B$24,IF(AA8="Střední riziko",Parametry!$B$25,IF(AA8="Watchlist",Parametry!$B$26,0)))+IFERROR(INDEX(Ciselniky!$I$3:$I$10,MATCH(AT8,Ciselniky!$F$3:$F$10,0)),0))) -> 0.05 | AD8: =IF(AA8="","",IF(OR(AA8="Stop",AW8="STOP"),"Stop",IF(AW8="MANUAL","Pouze manuálně",IF(AA8="Nízké riziko","Financovat",IF(AA8="Střední riziko","Financovat s limitem",IF(AA8="Watchlist","Pouze manuálně","Stop")))))) -> Financovat s limitem | AE8: =E8 -> 200000 | AF8: =SUMIF($A$6:$A$45,A8,$E$6:$E$45) -> 200000 | AG8: =Parametry!$B$28 -> 5800000 | AH8: =IFERROR(AE8/AF8,"") -> 1 | AI8: =IFERROR(AF8/Parametry!$B$28,"") -> 0.034482759 | AJ8: =IFERROR(AE8/Parametry!$B$28,"") -> 0.034482759 | AK8: =IF(OR(A8="",E8=""),"",MAX(0,100-IF(Parametry!$B$27="early",0.5,IF(Parametry!$B$27="growth",0.75,1))*(IF(AI8<=Parametry!$B$34,0,IF(AI8<=Parametry!$B$34+0.05,8,20))+IF(AH8<=Parametry!$B$35,0,12)+IF(AJ8<=Parametry!$B$36,0,12)))) -> 94 | AL8: =IF(OR(A8="",E8=""),"",IF(Parametry!$B$27="early",IF(OR(AI8>Parametry!$B$34*1.2,AH8>Parametry!$B$35*1.3),"EARLY STAGE EXCEPTION","OK"),IF(Parametry!$B$27="growth",IF(OR(AI8>Parametry!$B$34*1.35,AH8>Parametry!$B$35*1.4),"RED FLAG","OK"),IF(OR(AI8>Parametry!$B$34*1.2,AH8>Parametry!$B$35*1.3),"RED FLAG","OK")))) -> EARLY STAGE EXCEPTION | AM8: =IF(OR(A8="",E8=""),"",IF(COUNTIF($A$6:A8,A8)=1,AF8,"")) -> 200000 | AN8: =IF(A8="","",SUMPRODUCT(($A$6:$A$45=A8)*($E$6:$E$45)*((($C$6:$C$45="")+($C$6:$C$45="Otevřená"))>0))) -> 0 | AO8: =IF(OR(B8="",A8=""),"",SUMPRODUCT(($B$6:$B$45=B8)*($E$6:$E$45)*((($C$6:$C$45="")+($C$6:$C$45="Otevřená"))>0))) -> 100000 | AP8: =IF(OR(A8="",E8=""),"",IF(C8="Uhrazená","",N8)) | AQ8: =IF(OR(A8="",E8=""),"",IF(OR(AW8="STOP",AA8="Stop"),5,IF(OR(G8="ANO",H8="ANO"),4,IF(AL8="RED FLAG",4,IF(OR(AW8="MANUAL",AA8="Watchlist"),3,IF(OR(AL8="EARLY STAGE EXCEPTION",AA8="Střední riziko"),2,IF(AA8="Nízké riziko",1,5))))))) -> 2 | AR8: =IF(OR(A8="",E8=""),"",IF(OR(AQ8="",NOT(ISNUMBER(AQ8))),"",IF(AQ8=1,"Vhodné ke schválení",IF(AQ8=2,"Schválit s výhradou (koncentrace / early stage)",IF(AQ8=3,"Pouze manuálně - anchor rating / watchlist",IF(AQ8=4,"Zamítnout - spor, nesoulad nebo koncentrace",IF(AQ8=5,"STOP",""))))))) -> Schválit s výhradou (koncentrace / early stage) | AS8: =IF(A8="","",TEXT(Z8,"0") & " b | " & AA8 & " | " & AD8 & " | gate " & AW8 & " | rating " & AT8) -> 71 b | Střední riziko | Financovat s limitem | gate OK | rating BBB | AT8: =IF(A8="","",IF(COUNTIF(Ciselniky!$L$3:$L$200,A8)=0,"NR",IF(INDEX(Ciselniky!$M$3:$M$200,MATCH(A8,Ciselniky!$L$3:$L$200,0))="","NR",INDEX(Ciselniky!$M$3:$M$200,MATCH(A8,Ciselniky!$L$3:$L$200,0))))) -> BBB | AU8: =IF(A8="","",IF(AT8="NR","doplňit rating v Ciselniky",IFERROR(IF(INDEX(Ciselniky!$N$3:$N$200,MATCH(A8,Ciselniky!$L$3:$L$200,0))="","anchor master",INDEX(Ciselniky!$N$3:$N$200,MATCH(A8,Ciselniky!$L$3:$L$200,0))),"anchor master"))) -> demo / upravit | AV8: =IF(AT8="","",IFERROR(INDEX(Ciselniky!$G$3:$G$10,MATCH(AT8,Ciselniky!$F$3:$F$10,0)),0)) -> 65 | AW8: =IF(AT8="","",IFERROR(INDEX(Ciselniky!$J$3:$J$10,MATCH(AT8,Ciselniky!$F$3:$F$10,0)),"MANUAL")) -> OK | AX8: =IF(OR(A8="",E8=""),"",MAX(0,MIN(100,SUM(R8:Y8)))) -> 70 | AY8: =IF(OR(A8="",E8=""),"",AV8*Parametry!$B$41) -> 39 | AZ8: =IF(OR(A8="",E8=""),"",AX8*Parametry!$B$42) -> 17.5 | BA8: =IF(OR(A8="",E8=""),"",AK8*Parametry!$B$43) -> 14.1 | BB8: =IF(OR(A8="",E8=""),"",IF(AW8="STOP",-100,IF(AT8="BB",Parametry!$B$47,IF(AT8="NR",Parametry!$B$48,0)))) -> 0
A9: Maersk | B9: Dodavatel C | C9: Otevřená | D9: D004 | E9: 100000 | F9: 46183 | G9: NE | H9: NE | I9: =IF(A9="","",IF(AND(Parametry!$B$39="ANO",B9<>""),COUNTIFS(Historie!$A$2:$A$2000,A9,Historie!$B$2:$B$2000,B9,Historie!$E$2:$E$2000,"<>"),COUNTIFS(Historie!$A$2:$A$2000,A9,Historie!$E$2:$E$2000,"<>"))) -> 7 | J9: =IF(I9=0,"",IFERROR(IF(AND(Parametry!$B$39="ANO",B9<>""),AVERAGEIFS(Historie!$F$2:$F$2000,Historie!$A$2:$A$2000,A9,Historie!$B$2:$B$2000,B9,Historie!$E$2:$E$2000,"<>"),AVERAGEIFS(Historie!$F$2:$F$2000,Historie!$A$2:$A$2000,A9,Historie!$E$2:$E$2000,"<>")),"")) -> -0.14285714 | K9: =IF(I9=0,"",IFERROR(IF(AND(Parametry!$B$39="ANO",B9<>""),COUNTIFS(Historie!$A$2:$A$2000,A9,Historie!$B$2:$B$2000,B9,Historie!$E$2:$E$2000,"<>",Historie!$F$2:$F$2000,">0")/I9,COUNTIFS(Historie!$A$2:$A$2000,A9,Historie!$E$2:$E$2000,"<>",Historie!$F$2:$F$2000,">0")/I9),0)) -> 0.14285714 | L9: =IF(OR(A9="",I9=0),"",IFERROR(DATEDIF(IF(AND(Parametry!$B$39="ANO",B9<>""),_xludf.minifs(Historie!$E$2:$E$2000,Historie!$A$2:$A$2000,A9,Historie!$B$2:$B$2000,B9,Historie!$E$2:$E$2000,"<>"),_xludf.minifs(Historie!$E$2:$E$2000,Historie!$A$2:$A$2000,A9,Historie!$E$2:$E$2000,"<>")),IF(AND(Parametry!$B$39="ANO",B9<>""),_xludf.maxifs(Historie!$E$2:$E$2000,Historie!$A$2:$A$2000,A9,Historie!$B$2:$B$2000,B9,Historie!$E$2:$E$2000,"<>"),_xludf.maxifs(Historie!$E$2:$E$2000,Historie!$A$2:$A$2000,A9,Historie!$E$2:$E$2000,"<>")),"M"),0)) -> 0 | M9: =IF(A9="","",IFERROR(IF(AND(Parametry!$B$39="ANO",B9<>""),AVERAGEIFS(Historie!$C$2:$C$2000,Historie!$A$2:$A$2000,A9,Historie!$B$2:$B$2000,B9,Historie!$E$2:$E$2000,"<>"),AVERAGEIFS(Historie!$C$2:$C$2000,Historie!$A$2:$A$2000,A9,Historie!$E$2:$E$2000,"<>")),"")) -> 1847142.9 | N9: =IF(F9="","",F9-TODAY()) -> 63 | O9: =IF(OR(A9="",E9=""),"",IF(C9="Uhrazená","",N9)) -> 63 | P9: =IF(OR(A9="",E9=""),"",IF(I9=0,"ANO","NE")) -> NE | Q9: =IF(OR(A9="",E9="",M9=0),"",IFERROR(E9/M9,"")) -> 0.054137664 | R9: =IF(OR(A9="",E9=""),"",IF(I9>=Parametry!$B$4,Parametry!$B$9,0)) -> 40 | S9: =IF(OR(A9="",E9=""),"",IF(I9>0,IF(J9<=Parametry!$B$5,Parametry!$B$10,0),0)) -> 20 | T9: =IF(OR(A9="",E9=""),"",IF(I9>0,IF(K9<=Parametry!$B$6,Parametry!$B$11,0),0)) -> 15 | U9: =IF(OR(A9="",E9=""),"",IF(L9>=Parametry!$B$7,Parametry!$B$12,0)) -> 0 | V9: =IF(OR(A9="",E9=""),"",IF(M9>0,IF(Q9<=Parametry!$B$8,Parametry!$B$13,0),0)) -> 10 | W9: =IF(OR(A9="",E9=""),"",IF(P9="ANO",Parametry!$B$14,0)) -> 0 | X9: =IF(OR(A9="",E9=""),"",IF(G9="ANO",Parametry!$B$15,0)) -> 0 | Y9: =IF(OR(A9="",E9=""),"",IF(H9="ANO",Parametry!$B$16,0)) -> 0 | Z9: =IF(OR(A9="",E9=""),"",MAX(0,MIN(100,ROUND(AY9+AZ9+BA9+BB9,0)))) -> 89 | AA9: =IF(Z9="","",IF(AW9="STOP","Stop",IF(AW9="MANUAL",IF(Z9>=Parametry!$B$19,"Watchlist","Stop"),IF(Z9>=Parametry!$B$17,"Nízké riziko",IF(Z9>=Parametry!$B$18,"Střední riziko",IF(Z9>=Parametry!$B$19,"Watchlist","Stop")))))) -> Nízké riziko | AB9: =IF(AA9="","",MIN(IF(AA9="Nízké riziko",Parametry!$B$20,IF(AA9="Střední riziko",Parametry!$B$21,IF(AA9="Watchlist",Parametry!$B$22,Parametry!$B$23))),IFERROR(INDEX(Ciselniky!$H$3:$H$10,MATCH(AT9,Ciselniky!$F$3:$F$10,0)),0))) -> 0.8 | AC9: =IF(AA9="","",IF(AA9="Stop",0,IF(AA9="Nízké riziko",Parametry!$B$24,IF(AA9="Střední riziko",Parametry!$B$25,IF(AA9="Watchlist",Parametry!$B$26,0)))+IFERROR(INDEX(Ciselniky!$I$3:$I$10,MATCH(AT9,Ciselniky!$F$3:$F$10,0)),0))) -> 0.025 | AD9: =IF(AA9="","",IF(OR(AA9="Stop",AW9="STOP"),"Stop",IF(AW9="MANUAL","Pouze manuálně",IF(AA9="Nízké riziko","Financovat",IF(AA9="Střední riziko","Financovat s limitem",IF(AA9="Watchlist","Pouze manuálně","Stop")))))) -> Financovat | AE9: =E9 -> 100000 | AF9: =SUMIF($A$6:$A$45,A9,$E$6:$E$45) -> 3000000 | AG9: =Parametry!$B$28 -> 5800000 | AH9: =IFERROR(AE9/AF9,"") -> 0.033333333 | AI9: =IFERROR(AF9/Parametry!$B$28,"") -> 0.51724138 | AJ9: =IFERROR(AE9/Parametry!$B$28,"") -> 0.017241379 | AK9: =IF(OR(A9="",E9=""),"",MAX(0,100-IF(Parametry!$B$27="early",0.5,IF(Parametry!$B$27="growth",0.75,1))*(IF(AI9<=Parametry!$B$34,0,IF(AI9<=Parametry!$B$34+0.05,8,20))+IF(AH9<=Parametry!$B$35,0,12)+IF(AJ9<=Parametry!$B$36,0,12)))) -> 90 | AL9: =IF(OR(A9="",E9=""),"",IF(Parametry!$B$27="early",IF(OR(AI9>Parametry!$B$34*1.2,AH9>Parametry!$B$35*1.3),"EARLY STAGE EXCEPTION","OK"),IF(Parametry!$B$27="growth",IF(OR(AI9>Parametry!$B$34*1.35,AH9>Parametry!$B$35*1.4),"RED FLAG","OK"),IF(OR(AI9>Parametry!$B$34*1.2,AH9>Parametry!$B$35*1.3),"RED FLAG","OK")))) -> EARLY STAGE EXCEPTION | AM9: =IF(OR(A9="",E9=""),"",IF(COUNTIF($A$6:A9,A9)=1,AF9,"")) | AN9: =IF(A9="","",SUMPRODUCT(($A$6:$A$45=A9)*($E$6:$E$45)*((($C$6:$C$45="")+($C$6:$C$45="Otevřená"))>0))) -> 2600000 | AO9: =IF(OR(B9="",A9=""),"",SUMPRODUCT(($B$6:$B$45=B9)*($E$6:$E$45)*((($C$6:$C$45="")+($C$6:$C$45="Otevřená"))>0))) -> 100000 | AP9: =IF(OR(A9="",E9=""),"",IF(C9="Uhrazená","",N9)) -> 63 | AQ9: =IF(OR(A9="",E9=""),"",IF(OR(AW9="STOP",AA9="Stop"),5,IF(OR(G9="ANO",H9="ANO"),4,IF(AL9="RED FLAG",4,IF(OR(AW9="MANUAL",AA9="Watchlist"),3,IF(OR(AL9="EARLY STAGE EXCEPTION",AA9="Střední riziko"),2,IF(AA9="Nízké riziko",1,5))))))) -> 2 | AR9: =IF(OR(A9="",E9=""),"",IF(OR(AQ9="",NOT(ISNUMBER(AQ9))),"",IF(AQ9=1,"Vhodné ke schválení",IF(AQ9=2,"Schválit s výhradou (koncentrace / early stage)",IF(AQ9=3,"Pouze manuálně - anchor rating / watchlist",IF(AQ9=4,"Zamítnout - spor, nesoulad nebo koncentrace",IF(AQ9=5,"STOP",""))))))) -> Schválit s výhradou (koncentrace / early stage) | AS9: =IF(A9="","",TEXT(Z9,"0") & " b | " & AA9 & " | " & AD9 & " | gate " & AW9 & " | rating " & AT9) -> 89 b | Nízké riziko | Financovat | gate OK | rating AA | AT9: =IF(A9="","",IF(COUNTIF(Ciselniky!$L$3:$L$200,A9)=0,"NR",IF(INDEX(Ciselniky!$M$3:$M$200,MATCH(A9,Ciselniky!$L$3:$L$200,0))="","NR",INDEX(Ciselniky!$M$3:$M$200,MATCH(A9,Ciselniky!$L$3:$L$200,0))))) -> AA | AU9: =IF(A9="","",IF(AT9="NR","doplňit rating v Ciselniky",IFERROR(IF(INDEX(Ciselniky!$N$3:$N$200,MATCH(A9,Ciselniky!$L$3:$L$200,0))="","anchor master",INDEX(Ciselniky!$N$3:$N$200,MATCH(A9,Ciselniky!$L$3:$L$200,0))),"anchor master"))) -> doplňte interní / externí rating | AV9: =IF(AT9="","",IFERROR(INDEX(Ciselniky!$G$3:$G$10,MATCH(AT9,Ciselniky!$F$3:$F$10,0)),0)) -> 90 | AW9: =IF(AT9="","",IFERROR(INDEX(Ciselniky!$J$3:$J$10,MATCH(AT9,Ciselniky!$F$3:$F$10,0)),"MANUAL")) -> OK | AX9: =IF(OR(A9="",E9=""),"",MAX(0,MIN(100,SUM(R9:Y9)))) -> 85 | AY9: =IF(OR(A9="",E9=""),"",AV9*Parametry!$B$41) -> 54 | AZ9: =IF(OR(A9="",E9=""),"",AX9*Parametry!$B$42) -> 21.25 | BA9: =IF(OR(A9="",E9=""),"",AK9*Parametry!$B$43) -> 13.5 | BB9: =IF(OR(A9="",E9=""),"",IF(AW9="STOP",-100,IF(AT9="BB",Parametry!$B$47,IF(AT9="NR",Parametry!$B$48,0)))) -> 0
A10: Maersk | B10: AVS | C10: Uhrazená | D10: D005 | E10: 200000 | F10: 46183 | G10: NE | H10: NE | I10: =IF(A10="","",IF(AND(Parametry!$B$39="ANO",B10<>""),COUNTIFS(Historie!$A$2:$A$2000,A10,Historie!$B$2:$B$2000,B10,Historie!$E$2:$E$2000,"<>"),COUNTIFS(Historie!$A$2:$A$2000,A10,Historie!$E$2:$E$2000,"<>"))) -> 7 | J10: =IF(I10=0,"",IFERROR(IF(AND(Parametry!$B$39="ANO",B10<>""),AVERAGEIFS(Historie!$F$2:$F$2000,Historie!$A$2:$A$2000,A10,Historie!$B$2:$B$2000,B10,Historie!$E$2:$E$2000,"<>"),AVERAGEIFS(Historie!$F$2:$F$2000,Historie!$A$2:$A$2000,A10,Historie!$E$2:$E$2000,"<>")),"")) -> -0.14285714 | K10: =IF(I10=0,"",IFERROR(IF(AND(Parametry!$B$39="ANO",B10<>""),COUNTIFS(Historie!$A$2:$A$2000,A10,Historie!$B$2:$B$2000,B10,Historie!$E$2:$E$2000,"<>",Historie!$F$2:$F$2000,">0")/I10,COUNTIFS(Historie!$A$2:$A$2000,A10,Historie!$E$2:$E$2000,"<>",Historie!$F$2:$F$2000,">0")/I10),0)) -> 0.14285714 | L10: =IF(OR(A10="",I10=0),"",IFERROR(DATEDIF(IF(AND(Parametry!$B$39="ANO",B10<>""),_xludf.minifs(Historie!$E$2:$E$2000,Historie!$A$2:$A$2000,A10,Historie!$B$2:$B$2000,B10,Historie!$E$2:$E$2000,"<>"),_xludf.minifs(Historie!$E$2:$E$2000,Historie!$A$2:$A$2000,A10,Historie!$E$2:$E$2000,"<>")),IF(AND(Parametry!$B$39="ANO",B10<>""),_xludf.maxifs(Historie!$E$2:$E$2000,Historie!$A$2:$A$2000,A10,Historie!$B$2:$B$2000,B10,Historie!$E$2:$E$2000,"<>"),_xludf.maxifs(Historie!$E$2:$E$2000,Historie!$A$2:$A$2000,A10,Historie!$E$2:$E$2000,"<>")),"M"),0)) -> 0 | M10: =IF(A10="","",IFERROR(IF(AND(Parametry!$B$39="ANO",B10<>""),AVERAGEIFS(Historie!$C$2:$C$2000,Historie!$A$2:$A$2000,A10,Historie!$B$2:$B$2000,B10,Historie!$E$2:$E$2000,"<>"),AVERAGEIFS(Historie!$C$2:$C$2000,Historie!$A$2:$A$2000,A10,Historie!$E$2:$E$2000,"<>")),"")) -> 1847142.9 | N10: =IF(F10="","",F10-TODAY()) -> 63 | O10: =IF(OR(A10="",E10=""),"",IF(C10="Uhrazená","",N10)) | P10: =IF(OR(A10="",E10=""),"",IF(I10=0,"ANO","NE")) -> NE | Q10: =IF(OR(A10="",E10="",M10=0),"",IFERROR(E10/M10,"")) -> 0.10827533 | R10: =IF(OR(A10="",E10=""),"",IF(I10>=Parametry!$B$4,Parametry!$B$9,0)) -> 40 | S10: =IF(OR(A10="",E10=""),"",IF(I10>0,IF(J10<=Parametry!$B$5,Parametry!$B$10,0),0)) -> 20 | T10: =IF(OR(A10="",E10=""),"",IF(I10>0,IF(K10<=Parametry!$B$6,Parametry!$B$11,0),0)) -> 15 | U10: =IF(OR(A10="",E10=""),"",IF(L10>=Parametry!$B$7,Parametry!$B$12,0)) -> 0 | V10: =IF(OR(A10="",E10=""),"",IF(M10>0,IF(Q10<=Parametry!$B$8,Parametry!$B$13,0),0)) -> 10 | W10: =IF(OR(A10="",E10=""),"",IF(P10="ANO",Parametry!$B$14,0)) -> 0 | X10: =IF(OR(A10="",E10=""),"",IF(G10="ANO",Parametry!$B$15,0)) -> 0 | Y10: =IF(OR(A10="",E10=""),"",IF(H10="ANO",Parametry!$B$16,0)) -> 0 | Z10: =IF(OR(A10="",E10=""),"",MAX(0,MIN(100,ROUND(AY10+AZ10+BA10+BB10,0)))) -> 89 | AA10: =IF(Z10="","",IF(AW10="STOP","Stop",IF(AW10="MANUAL",IF(Z10>=Parametry!$B$19,"Watchlist","Stop"),IF(Z10>=Parametry!$B$17,"Nízké riziko",IF(Z10>=Parametry!$B$18,"Střední riziko",IF(Z10>=Parametry!$B$19,"Watchlist","Stop")))))) -> Nízké riziko | AB10: =IF(AA10="","",MIN(IF(AA10="Nízké riziko",Parametry!$B$20,IF(AA10="Střední riziko",Parametry!$B$21,IF(AA10="Watchlist",Parametry!$B$22,Parametry!$B$23))),IFERROR(INDEX(Ciselniky!$H$3:$H$10,MATCH(AT10,Ciselniky!$F$3:$F$10,0)),0))) -> 0.8 | AC10: =IF(AA10="","",IF(AA10="Stop",0,IF(AA10="Nízké riziko",Parametry!$B$24,IF(AA10="Střední riziko",Parametry!$B$25,IF(AA10="Watchlist",Parametry!$B$26,0)))+IFERROR(INDEX(Ciselniky!$I$3:$I$10,MATCH(AT10,Ciselniky!$F$3:$F$10,0)),0))) -> 0.025 | AD10: =IF(AA10="","",IF(OR(AA10="Stop",AW10="STOP"),"Stop",IF(AW10="MANUAL","Pouze manuálně",IF(AA10="Nízké riziko","Financovat",IF(AA10="Střední riziko","Financovat s limitem",IF(AA10="Watchlist","Pouze manuálně","Stop")))))) -> Financovat | AE10: =E10 -> 200000 | AF10: =SUMIF($A$6:$A$45,A10,$E$6:$E$45) -> 3000000 | AG10: =Parametry!$B$28 -> 5800000 | AH10: =IFERROR(AE10/AF10,"") -> 0.066666667 | AI10: =IFERROR(AF10/Parametry!$B$28,"") -> 0.51724138 | AJ10: =IFERROR(AE10/Parametry!$B$28,"") -> 0.034482759 | AK10: =IF(OR(A10="",E10=""),"",MAX(0,100-IF(Parametry!$B$27="early",0.5,IF(Parametry!$B$27="growth",0.75,1))*(IF(AI10<=Parametry!$B$34,0,IF(AI10<=Parametry!$B$34+0.05,8,20))+IF(AH10<=Parametry!$B$35,0,12)+IF(AJ10<=Parametry!$B$36,0,12)))) -> 90 | AL10: =IF(OR(A10="",E10=""),"",IF(Parametry!$B$27="early",IF(OR(AI10>Parametry!$B$34*1.2,AH10>Parametry!$B$35*1.3),"EARLY STAGE EXCEPTION","OK"),IF(Parametry!$B$27="growth",IF(OR(AI10>Parametry!$B$34*1.35,AH10>Parametry!$B$35*1.4),"RED FLAG","OK"),IF(OR(AI10>Parametry!$B$34*1.2,AH10>Parametry!$B$35*1.3),"RED FLAG","OK")))) -> EARLY STAGE EXCEPTION | AM10: =IF(OR(A10="",E10=""),"",IF(COUNTIF($A$6:A10,A10)=1,AF10,"")) | AN10: =IF(A10="","",SUMPRODUCT(($A$6:$A$45=A10)*($E$6:$E$45)*((($C$6:$C$45="")+($C$6:$C$45="Otevřená"))>0))) -> 2600000 | AO10: =IF(OR(B10="",A10=""),"",SUMPRODUCT(($B$6:$B$45=B10)*($E$6:$E$45)*((($C$6:$C$45="")+($C$6:$C$45="Otevřená"))>0))) -> 2500000 | AP10: =IF(OR(A10="",E10=""),"",IF(C10="Uhrazená","",N10)) | AQ10: =IF(OR(A10="",E10=""),"",IF(OR(AW10="STOP",AA10="Stop"),5,IF(OR(G10="ANO",H10="ANO"),4,IF(AL10="RED FLAG",4,IF(OR(AW10="MANUAL",AA10="Watchlist"),3,IF(OR(AL10="EARLY STAGE EXCEPTION",AA10="Střední riziko"),2,IF(AA10="Nízké riziko",1,5))))))) -> 2 | AR10: =IF(OR(A10="",E10=""),"",IF(OR(AQ10="",NOT(ISNUMBER(AQ10))),"",IF(AQ10=1,"Vhodné ke schválení",IF(AQ10=2,"Schválit s výhradou (koncentrace / early stage)",IF(AQ10=3,"Pouze manuálně - anchor rating / watchlist",IF(AQ10=4,"Zamítnout - spor, nesoulad nebo koncentrace",IF(AQ10=5,"STOP",""))))))) -> Schválit s výhradou (koncentrace / early stage) | AS10: =IF(A10="","",TEXT(Z10,"0") & " b | " & AA10 & " | " & AD10 & " | gate " & AW10 & " | rating " & AT10) -> 89 b | Nízké riziko | Financovat | gate OK | rating AA | AT10: =IF(A10="","",IF(COUNTIF(Ciselniky!$L$3:$L$200,A10)=0,"NR",IF(INDEX(Ciselniky!$M$3:$M$200,MATCH(A10,Ciselniky!$L$3:$L$200,0))="","NR",INDEX(Ciselniky!$M$3:$M$200,MATCH(A10,Ciselniky!$L$3:$L$200,0))))) -> AA | AU10: =IF(A10="","",IF(AT10="NR","doplňit rating v Ciselniky",IFERROR(IF(INDEX(Ciselniky!$N$3:$N$200,MATCH(A10,Ciselniky!$L$3:$L$200,0))="","anchor master",INDEX(Ciselniky!$N$3:$N$200,MATCH(A10,Ciselniky!$L$3:$L$200,0))),"anchor master"))) -> doplňte interní / externí rating | AV10: =IF(AT10="","",IFERROR(INDEX(Ciselniky!$G$3:$G$10,MATCH(AT10,Ciselniky!$F$3:$F$10,0)),0)) -> 90 | AW10: =IF(AT10="","",IFERROR(INDEX(Ciselniky!$J$3:$J$10,MATCH(AT10,Ciselniky!$F$3:$F$10,0)),"MANUAL")) -> OK | AX10: =IF(OR(A10="",E10=""),"",MAX(0,MIN(100,SUM(R10:Y10)))) -> 85 | AY10: =IF(OR(A10="",E10=""),"",AV10*Parametry!$B$41) -> 54 | AZ10: =IF(OR(A10="",E10=""),"",AX10*Parametry!$B$42) -> 21.25 | BA10: =IF(OR(A10="",E10=""),"",AK10*Parametry!$B$43) -> 13.5 | BB10: =IF(OR(A10="",E10=""),"",IF(AW10="STOP",-100,IF(AT10="BB",Parametry!$B$47,IF(AT10="NR",Parametry!$B$48,0)))) -> 0
A11: Tesco | B11: Bruggy | C11: Otevřená | D11: D006 | E11: 850000 | F11: 46184 | G11: NE | H11: NE | I11: =IF(A11="","",IF(AND(Parametry!$B$39="ANO",B11<>""),COUNTIFS(Historie!$A$2:$A$2000,A11,Historie!$B$2:$B$2000,B11,Historie!$E$2:$E$2000,"<>"),COUNTIFS(Historie!$A$2:$A$2000,A11,Historie!$E$2:$E$2000,"<>"))) -> 1 | J11: =IF(I11=0,"",IFERROR(IF(AND(Parametry!$B$39="ANO",B11<>""),AVERAGEIFS(Historie!$F$2:$F$2000,Historie!$A$2:$A$2000,A11,Historie!$B$2:$B$2000,B11,Historie!$E$2:$E$2000,"<>"),AVERAGEIFS(Historie!$F$2:$F$2000,Historie!$A$2:$A$2000,A11,Historie!$E$2:$E$2000,"<>")),"")) -> 5 | K11: =IF(I11=0,"",IFERROR(IF(AND(Parametry!$B$39="ANO",B11<>""),COUNTIFS(Historie!$A$2:$A$2000,A11,Historie!$B$2:$B$2000,B11,Historie!$E$2:$E$2000,"<>",Historie!$F$2:$F$2000,">0")/I11,COUNTIFS(Historie!$A$2:$A$2000,A11,Historie!$E$2:$E$2000,"<>",Historie!$F$2:$F$2000,">0")/I11),0)) -> 1 | L11: =IF(OR(A11="",I11=0),"",IFERROR(DATEDIF(IF(AND(Parametry!$B$39="ANO",B11<>""),_xludf.minifs(Historie!$E$2:$E$2000,Historie!$A$2:$A$2000,A11,Historie!$B$2:$B$2000,B11,Historie!$E$2:$E$2000,"<>"),_xludf.minifs(Historie!$E$2:$E$2000,Historie!$A$2:$A$2000,A11,Historie!$E$2:$E$2000,"<>")),IF(AND(Parametry!$B$39="ANO",B11<>""),_xludf.maxifs(Historie!$E$2:$E$2000,Historie!$A$2:$A$2000,A11,Historie!$B$2:$B$2000,B11,Historie!$E$2:$E$2000,"<>"),_xludf.maxifs(Historie!$E$2:$E$2000,Historie!$A$2:$A$2000,A11,Historie!$E$2:$E$2000,"<>")),"M"),0)) -> 0 | M11: =IF(A11="","",IFERROR(IF(AND(Parametry!$B$39="ANO",B11<>""),AVERAGEIFS(Historie!$C$2:$C$2000,Historie!$A$2:$A$2000,A11,Historie!$B$2:$B$2000,B11,Historie!$E$2:$E$2000,"<>"),AVERAGEIFS(Historie!$C$2:$C$2000,Historie!$A$2:$A$2000,A11,Historie!$E$2:$E$2000,"<>")),"")) -> 975000 | N11: =IF(F11="","",F11-TODAY()) -> 64 | O11: =IF(OR(A11="",E11=""),"",IF(C11="Uhrazená","",N11)) -> 64 | P11: =IF(OR(A11="",E11=""),"",IF(I11=0,"ANO","NE")) -> NE | Q11: =IF(OR(A11="",E11="",M11=0),"",IFERROR(E11/M11,"")) -> 0.87179487 | R11: =IF(OR(A11="",E11=""),"",IF(I11>=Parametry!$B$4,Parametry!$B$9,0)) -> 0 | S11: =IF(OR(A11="",E11=""),"",IF(I11>0,IF(J11<=Parametry!$B$5,Parametry!$B$10,0),0)) -> 20 | T11: =IF(OR(A11="",E11=""),"",IF(I11>0,IF(K11<=Parametry!$B$6,Parametry!$B$11,0),0)) -> 0 | U11: =IF(OR(A11="",E11=""),"",IF(L11>=Parametry!$B$7,Parametry!$B$12,0)) -> 0 | V11: =IF(OR(A11="",E11=""),"",IF(M11>0,IF(Q11<=Parametry!$B$8,Parametry!$B$13,0),0)) -> 10 | W11: =IF(OR(A11="",E11=""),"",IF(P11="ANO",Parametry!$B$14,0)) -> 0 | X11: =IF(OR(A11="",E11=""),"",IF(G11="ANO",Parametry!$B$15,0)) -> 0 | Y11: =IF(OR(A11="",E11=""),"",IF(H11="ANO",Parametry!$B$16,0)) -> 0 | Z11: =IF(OR(A11="",E11=""),"",MAX(0,MIN(100,ROUND(AY11+AZ11+BA11+BB11,0)))) -> 70 | AA11: =IF(Z11="","",IF(AW11="STOP","Stop",IF(AW11="MANUAL",IF(Z11>=Parametry!$B$19,"Watchlist","Stop"),IF(Z11>=Parametry!$B$17,"Nízké riziko",IF(Z11>=Parametry!$B$18,"Střední riziko",IF(Z11>=Parametry!$B$19,"Watchlist","Stop")))))) -> Střední riziko | AB11: =IF(AA11="","",MIN(IF(AA11="Nízké riziko",Parametry!$B$20,IF(AA11="Střední riziko",Parametry!$B$21,IF(AA11="Watchlist",Parametry!$B$22,Parametry!$B$23))),IFERROR(INDEX(Ciselniky!$H$3:$H$10,MATCH(AT11,Ciselniky!$F$3:$F$10,0)),0))) -> 0.75 | AC11: =IF(AA11="","",IF(AA11="Stop",0,IF(AA11="Nízké riziko",Parametry!$B$24,IF(AA11="Střední riziko",Parametry!$B$25,IF(AA11="Watchlist",Parametry!$B$26,0)))+IFERROR(INDEX(Ciselniky!$I$3:$I$10,MATCH(AT11,Ciselniky!$F$3:$F$10,0)),0))) -> 0.045 | AD11: =IF(AA11="","",IF(OR(AA11="Stop",AW11="STOP"),"Stop",IF(AW11="MANUAL","Pouze manuálně",IF(AA11="Nízké riziko","Financovat",IF(AA11="Střední riziko","Financovat s limitem",IF(AA11="Watchlist","Pouze manuálně","Stop")))))) -> Financovat s limitem | AE11: =E11 -> 850000 | AF11: =SUMIF($A$6:$A$45,A11,$E$6:$E$45) -> 1700000 | AG11: =Parametry!$B$28 -> 5800000 | AH11: =IFERROR(AE11/AF11,"") -> 0.5 | AI11: =IFERROR(AF11/Parametry!$B$28,"") -> 0.29310345 | AJ11: =IFERROR(AE11/Parametry!$B$28,"") -> 0.14655172 | AK11: =IF(OR(A11="",E11=""),"",MAX(0,100-IF(Parametry!$B$27="early",0.5,IF(Parametry!$B$27="growth",0.75,1))*(IF(AI11<=Parametry!$B$34,0,IF(AI11<=Parametry!$B$34+0.05,8,20))+IF(AH11<=Parametry!$B$35,0,12)+IF(AJ11<=Parametry!$B$36,0,12)))) -> 94 | AL11: =IF(OR(A11="",E11=""),"",IF(Parametry!$B$27="early",IF(OR(AI11>Parametry!$B$34*1.2,AH11>Parametry!$B$35*1.3),"EARLY STAGE EXCEPTION","OK"),IF(Parametry!$B$27="growth",IF(OR(AI11>Parametry!$B$34*1.35,AH11>Parametry!$B$35*1.4),"RED FLAG","OK"),IF(OR(AI11>Parametry!$B$34*1.2,AH11>Parametry!$B$35*1.3),"RED FLAG","OK")))) -> EARLY STAGE EXCEPTION | AM11: =IF(OR(A11="",E11=""),"",IF(COUNTIF($A$6:A11,A11)=1,AF11,"")) -> 1700000 | AN11: =IF(A11="","",SUMPRODUCT(($A$6:$A$45=A11)*($E$6:$E$45)*((($C$6:$C$45="")+($C$6:$C$45="Otevřená"))>0))) -> 1700000 | AO11: =IF(OR(B11="",A11=""),"",SUMPRODUCT(($B$6:$B$45=B11)*($E$6:$E$45)*((($C$6:$C$45="")+($C$6:$C$45="Otevřená"))>0))) -> 1700000 | AP11: =IF(OR(A11="",E11=""),"",IF(C11="Uhrazená","",N11)) -> 64 | AQ11: =IF(OR(A11="",E11=""),"",IF(OR(AW11="STOP",AA11="Stop"),5,IF(OR(G11="ANO",H11="ANO"),4,IF(AL11="RED FLAG",4,IF(OR(AW11="MANUAL",AA11="Watchlist"),3,IF(OR(AL11="EARLY STAGE EXCEPTION",AA11="Střední riziko"),2,IF(AA11="Nízké riziko",1,5))))))) -> 2 | AR11: =IF(OR(A11="",E11=""),"",IF(OR(AQ11="",NOT(ISNUMBER(AQ11))),"",IF(AQ11=1,"Vhodné ke schválení",IF(AQ11=2,"Schválit s výhradou (koncentrace / early stage)",IF(AQ11=3,"Pouze manuálně - anchor rating / watchlist",IF(AQ11=4,"Zamítnout - spor, nesoulad nebo koncentrace",IF(AQ11=5,"STOP",""))))))) -> Schválit s výhradou (koncentrace / early stage) | AS11: =IF(A11="","",TEXT(Z11,"0") & " b | " & AA11 & " | " & AD11 & " | gate " & AW11 & " | rating " & AT11) -> 70 b | Střední riziko | Financovat s limitem | gate OK | rating A | AT11: =IF(A11="","",IF(COUNTIF(Ciselniky!$L$3:$L$200,A11)=0,"NR",IF(INDEX(Ciselniky!$M$3:$M$200,MATCH(A11,Ciselniky!$L$3:$L$200,0))="","NR",INDEX(Ciselniky!$M$3:$M$200,MATCH(A11,Ciselniky!$L$3:$L$200,0))))) -> A | AU11: =IF(A11="","",IF(AT11="NR","doplňit rating v Ciselniky",IFERROR(IF(INDEX(Ciselniky!$N$3:$N$200,MATCH(A11,Ciselniky!$L$3:$L$200,0))="","anchor master",INDEX(Ciselniky!$N$3:$N$200,MATCH(A11,Ciselniky!$L$3:$L$200,0))),"anchor master"))) -> doplňte interní / externí rating | AV11: =IF(AT11="","",IFERROR(INDEX(Ciselniky!$G$3:$G$10,MATCH(AT11,Ciselniky!$F$3:$F$10,0)),0)) -> 80 | AW11: =IF(AT11="","",IFERROR(INDEX(Ciselniky!$J$3:$J$10,MATCH(AT11,Ciselniky!$F$3:$F$10,0)),"MANUAL")) -> OK | AX11: =IF(OR(A11="",E11=""),"",MAX(0,MIN(100,SUM(R11:Y11)))) -> 30 | AY11: =IF(OR(A11="",E11=""),"",AV11*Parametry!$B$41) -> 48 | AZ11: =IF(OR(A11="",E11=""),"",AX11*Parametry!$B$42) -> 7.5 | BA11: =IF(OR(A11="",E11=""),"",AK11*Parametry!$B$43) -> 14.1 | BB11: =IF(OR(A11="",E11=""),"",IF(AW11="STOP",-100,IF(AT11="BB",Parametry!$B$47,IF(AT11="NR",Parametry!$B$48,0)))) -> 0
A12: Maersk | B12: AVS | C12: Uhrazená | D12: D007 | E12: 200000 | F12: 46183 | G12: NE | H12: NE | I12: =IF(A12="","",IF(AND(Parametry!$B$39="ANO",B12<>""),COUNTIFS(Historie!$A$2:$A$2000,A12,Historie!$B$2:$B$2000,B12,Historie!$E$2:$E$2000,"<>"),COUNTIFS(Historie!$A$2:$A$2000,A12,Historie!$E$2:$E$2000,"<>"))) -> 7 | J12: =IF(I12=0,"",IFERROR(IF(AND(Parametry!$B$39="ANO",B12<>""),AVERAGEIFS(Historie!$F$2:$F$2000,Historie!$A$2:$A$2000,A12,Historie!$B$2:$B$2000,B12,Historie!$E$2:$E$2000,"<>"),AVERAGEIFS(Historie!$F$2:$F$2000,Historie!$A$2:$A$2000,A12,Historie!$E$2:$E$2000,"<>")),"")) -> -0.14285714 | K12: =IF(I12=0,"",IFERROR(IF(AND(Parametry!$B$39="ANO",B12<>""),COUNTIFS(Historie!$A$2:$A$2000,A12,Historie!$B$2:$B$2000,B12,Historie!$E$2:$E$2000,"<>",Historie!$F$2:$F$2000,">0")/I12,COUNTIFS(Historie!$A$2:$A$2000,A12,Historie!$E$2:$E$2000,"<>",Historie!$F$2:$F$2000,">0")/I12),0)) -> 0.14285714 | L12: =IF(OR(A12="",I12=0),"",IFERROR(DATEDIF(IF(AND(Parametry!$B$39="ANO",B12<>""),_xludf.minifs(Historie!$E$2:$E$2000,Historie!$A$2:$A$2000,A12,Historie!$B$2:$B$2000,B12,Historie!$E$2:$E$2000,"<>"),_xludf.minifs(Historie!$E$2:$E$2000,Historie!$A$2:$A$2000,A12,Historie!$E$2:$E$2000,"<>")),IF(AND(Parametry!$B$39="ANO",B12<>""),_xludf.maxifs(Historie!$E$2:$E$2000,Historie!$A$2:$A$2000,A12,Historie!$B$2:$B$2000,B12,Historie!$E$2:$E$2000,"<>"),_xludf.maxifs(Historie!$E$2:$E$2000,Historie!$A$2:$A$2000,A12,Historie!$E$2:$E$2000,"<>")),"M"),0)) -> 0 | M12: =IF(A12="","",IFERROR(IF(AND(Parametry!$B$39="ANO",B12<>""),AVERAGEIFS(Historie!$C$2:$C$2000,Historie!$A$2:$A$2000,A12,Historie!$B$2:$B$2000,B12,Historie!$E$2:$E$2000,"<>"),AVERAGEIFS(Historie!$C$2:$C$2000,Historie!$A$2:$A$2000,A12,Historie!$E$2:$E$2000,"<>")),"")) -> 1847142.9 | N12: =IF(F12="","",F12-TODAY()) -> 63 | O12: =IF(OR(A12="",E12=""),"",IF(C12="Uhrazená","",N12)) | P12: =IF(OR(A12="",E12=""),"",IF(I12=0,"ANO","NE")) -> NE | Q12: =IF(OR(A12="",E12="",M12=0),"",IFERROR(E12/M12,"")) -> 0.10827533 | R12: =IF(OR(A12="",E12=""),"",IF(I12>=Parametry!$B$4,Parametry!$B$9,0)) -> 40 | S12: =IF(OR(A12="",E12=""),"",IF(I12>0,IF(J12<=Parametry!$B$5,Parametry!$B$10,0),0)) -> 20 | T12: =IF(OR(A12="",E12=""),"",IF(I12>0,IF(K12<=Parametry!$B$6,Parametry!$B$11,0),0)) -> 15 | U12: =IF(OR(A12="",E12=""),"",IF(L12>=Parametry!$B$7,Parametry!$B$12,0)) -> 0 | V12: =IF(OR(A12="",E12=""),"",IF(M12>0,IF(Q12<=Parametry!$B$8,Parametry!$B$13,0),0)) -> 10 | W12: =IF(OR(A12="",E12=""),"",IF(P12="ANO",Parametry!$B$14,0)) -> 0 | X12: =IF(OR(A12="",E12=""),"",IF(G12="ANO",Parametry!$B$15,0)) -> 0 | Y12: =IF(OR(A12="",E12=""),"",IF(H12="ANO",Parametry!$B$16,0)) -> 0 | Z12: =IF(OR(A12="",E12=""),"",MAX(0,MIN(100,ROUND(AY12+AZ12+BA12+BB12,0)))) -> 89 | AA12: =IF(Z12="","",IF(AW12="STOP","Stop",IF(AW12="MANUAL",IF(Z12>=Parametry!$B$19,"Watchlist","Stop"),IF(Z12>=Parametry!$B$17,"Nízké riziko",IF(Z12>=Parametry!$B$18,"Střední riziko",IF(Z12>=Parametry!$B$19,"Watchlist","Stop")))))) -> Nízké riziko | AB12: =IF(AA12="","",MIN(IF(AA12="Nízké riziko",Parametry!$B$20,IF(AA12="Střední riziko",Parametry!$B$21,IF(AA12="Watchlist",Parametry!$B$22,Parametry!$B$23))),IFERROR(INDEX(Ciselniky!$H$3:$H$10,MATCH(AT12,Ciselniky!$F$3:$F$10,0)),0))) -> 0.8 | AC12: =IF(AA12="","",IF(AA12="Stop",0,IF(AA12="Nízké riziko",Parametry!$B$24,IF(AA12="Střední riziko",Parametry!$B$25,IF(AA12="Watchlist",Parametry!$B$26,0)))+IFERROR(INDEX(Ciselniky!$I$3:$I$10,MATCH(AT12,Ciselniky!$F$3:$F$10,0)),0))) -> 0.025 | AD12: =IF(AA12="","",IF(OR(AA12="Stop",AW12="STOP"),"Stop",IF(AW12="MANUAL","Pouze manuálně",IF(AA12="Nízké riziko","Financovat",IF(AA12="Střední riziko","Financovat s limitem",IF(AA12="Watchlist","Pouze manuálně","Stop")))))) -> Financovat | AE12: =E12 -> 200000 | AF12: =SUMIF($A$6:$A$45,A12,$E$6:$E$45) -> 3000000 | AG12: =Parametry!$B$28 -> 5800000 | AH12: =IFERROR(AE12/AF12,"") -> 0.066666667 | AI12: =IFERROR(AF12/Parametry!$B$28,"") -> 0.51724138 | AJ12: =IFERROR(AE12/Parametry!$B$28,"") -> 0.034482759 | AK12: =IF(OR(A12="",E12=""),"",MAX(0,100-IF(Parametry!$B$27="early",0.5,IF(Parametry!$B$27="growth",0.75,1))*(IF(AI12<=Parametry!$B$34,0,IF(AI12<=Parametry!$B$34+0.05,8,20))+IF(AH12<=Parametry!$B$35,0,12)+IF(AJ12<=Parametry!$B$36,0,12)))) -> 90 | AL12: =IF(OR(A12="",E12=""),"",IF(Parametry!$B$27="early",IF(OR(AI12>Parametry!$B$34*1.2,AH12>Parametry!$B$35*1.3),"EARLY STAGE EXCEPTION","OK"),IF(Parametry!$B$27="growth",IF(OR(AI12>Parametry!$B$34*1.35,AH12>Parametry!$B$35*1.4),"RED FLAG","OK"),IF(OR(AI12>Parametry!$B$34*1.2,AH12>Parametry!$B$35*1.3),"RED FLAG","OK")))) -> EARLY STAGE EXCEPTION | AM12: =IF(OR(A12="",E12=""),"",IF(COUNTIF($A$6:A12,A12)=1,AF12,"")) | AN12: =IF(A12="","",SUMPRODUCT(($A$6:$A$45=A12)*($E$6:$E$45)*((($C$6:$C$45="")+($C$6:$C$45="Otevřená"))>0))) -> 2600000 | AO12: =IF(OR(B12="",A12=""),"",SUMPRODUCT(($B$6:$B$45=B12)*($E$6:$E$45)*((($C$6:$C$45="")+($C$6:$C$45="Otevřená"))>0))) -> 2500000 | AP12: =IF(OR(A12="",E12=""),"",IF(C12="Uhrazená","",N12)) | AQ12: =IF(OR(A12="",E12=""),"",IF(OR(AW12="STOP",AA12="Stop"),5,IF(OR(G12="ANO",H12="ANO"),4,IF(AL12="RED FLAG",4,IF(OR(AW12="MANUAL",AA12="Watchlist"),3,IF(OR(AL12="EARLY STAGE EXCEPTION",AA12="Střední riziko"),2,IF(AA12="Nízké riziko",1,5))))))) -> 2 | AR12: =IF(OR(A12="",E12=""),"",IF(OR(AQ12="",NOT(ISNUMBER(AQ12))),"",IF(AQ12=1,"Vhodné ke schválení",IF(AQ12=2,"Schválit s výhradou (koncentrace / early stage)",IF(AQ12=3,"Pouze manuálně - anchor rating / watchlist",IF(AQ12=4,"Zamítnout - spor, nesoulad nebo koncentrace",IF(AQ12=5,"STOP",""))))))) -> Schválit s výhradou (koncentrace / early stage) | AS12: =IF(A12="","",TEXT(Z12,"0") & " b | " & AA12 & " | " & AD12 & " | gate " & AW12 & " | rating " & AT12) -> 89 b | Nízké riziko | Financovat | gate OK | rating AA | AT12: =IF(A12="","",IF(COUNTIF(Ciselniky!$L$3:$L$200,A12)=0,"NR",IF(INDEX(Ciselniky!$M$3:$M$200,MATCH(A12,Ciselniky!$L$3:$L$200,0))="","NR",INDEX(Ciselniky!$M$3:$M$200,MATCH(A12,Ciselniky!$L$3:$L$200,0))))) -> AA | AU12: =IF(A12="","",IF(AT12="NR","doplňit rating v Ciselniky",IFERROR(IF(INDEX(Ciselniky!$N$3:$N$200,MATCH(A12,Ciselniky!$L$3:$L$200,0))="","anchor master",INDEX(Ciselniky!$N$3:$N$200,MATCH(A12,Ciselniky!$L$3:$L$200,0))),"anchor master"))) -> doplňte interní / externí rating | AV12: =IF(AT12="","",IFERROR(INDEX(Ciselniky!$G$3:$G$10,MATCH(AT12,Ciselniky!$F$3:$F$10,0)),0)) -> 90 | AW12: =IF(AT12="","",IFERROR(INDEX(Ciselniky!$J$3:$J$10,MATCH(AT12,Ciselniky!$F$3:$F$10,0)),"MANUAL")) -> OK | AX12: =IF(OR(A12="",E12=""),"",MAX(0,MIN(100,SUM(R12:Y12)))) -> 85 | AY12: =IF(OR(A12="",E12=""),"",AV12*Parametry!$B$41) -> 54 | AZ12: =IF(OR(A12="",E12=""),"",AX12*Parametry!$B$42) -> 21.25 | BA12: =IF(OR(A12="",E12=""),"",AK12*Parametry!$B$43) -> 13.5 | BB12: =IF(OR(A12="",E12=""),"",IF(AW12="STOP",-100,IF(AT12="BB",Parametry!$B$47,IF(AT12="NR",Parametry!$B$48,0)))) -> 0
